<?xml version="1.0"?>
<robot name"cm">

  <link name="link1">
    <inertial>
        <mass value="10" />
        <inertia ixx="0.4" ixy="0.0" ixz="0.0" iyy="0.4" iyz="0.0" izz="0.2"/>
    </inertial>
    <collision>
      <geometry>
        <cylinder radius="0.25" length="0.1" />
      </geometry>
        </collision>
    <visual>
      <geometry>
        <cylinder radius="0.25" length="0.1" />
      </geometry>
    </visual>
  </link>


  <link name="link2">
    <inertial>
        <mass value="0.18" />
        <inertia ixx="0.0002835" ixy="0.0" ixz="0.0" iyy="0.0002835" iyz="0.0" izz="0.000324" />
    </inertial>
    <origin rpy="0.0 0.0 0.0" xyz="0.0 0.0 0.0" />
    <collision>
      <geometry>
        <cylinder radius="0.25" length="0.1"/>
      </geometry>
    </collision>
    <visual>
      <geometry>
        <cylinder radius="0.25" length="0.1"/>
      </geometry>
    </visual>
  </link>

  <!--joint-->
  <joint name="joint1" type="continuous">
    <parent link="link1"/>
    <child link="link2"/>
    <axis xyz="1 0 0"/>
    <origin xyz="0.0 0.0 0.2" rpy="0.0 0.0 0.0"/> 
  </joint>

  <!--   GAZEBO - ROS Control Plugin -->

  <gazebo>
    <plugin name="gazebo_ros_control" filename="libgazebo_ros_control.so">
      <robotNamespace>/cm_model</robotNamespace>
      <robotSimType>gazebo_ros_control/DefaultRobotHWSim</robotSimType>
      <legacyModeNS>true</legacyModeNS>
    </plugin>
  </gazebo>

 <transmission name="link1_to_link2_trans">
    <type>transmission_interface/SimpleTransmission</type>
    <actuator name="motor1">
      <mechanicalReduction>1</mechanicalReduction>
    </actuator>
    <joint name="joint1">
      <hardwareInterface>hardware_interface/VelocityJointInterface</hardwareInterface>
    </joint>
  </transmission>
</robot>